File: Manufacturing/Material_Testing_Data/Group 10/Group 10 Horizontal/Test 97 Group_10_Horizontal_03292019 105927 AM.csv
Time (sec),Force (N),Position (mm),Stress (Pa),Strain (%)
2.23,48.5,0.067100,2300000,0.132
4.25,64.7,0.13480,3070000,0.265
6.25,65.6,0.20310,3110000,0.400
8.26,66.1,0.26770,3130000,0.527
10.3,68.3,0.33540,3240000,0.660
12.3,95.2,0.40310,4510000,0.794
14.3,137,0.47050,6510000,0.926
16.3,178,0.53810,8410000,1.06
18.3,215,0.60350,10200000,1.19
20.3,251,0.67100,11900000,1.32
22.4,286,0.73860,13500000,1.45
24.4,320,0.80660,15200000,1.59
26.4,352,0.87420,16700000,1.72
28.4,380,0.93900,18000000,1.85
30.4,409,1.0070,19400000,1.98
32.4,436,1.0750,20600000,2.12
34.4,459,1.1400,21700000,2.24
36.4,483,1.2076,22900000,2.38
38.5,505,1.2753,23900000,2.51
40.5,525,1.3428,24900000,2.64
42.5,544,1.4105,25800000,2.78
44.5,562,1.4758,26600000,2.91
46.5,580,1.5432,27500000,3.04
48.5,595,1.6110,28200000,3.17
50.5,611,1.6790,28900000,3.31
52.6,624,1.7463,29600000,3.44
54.6,636,1.8115,30100000,3.57
56.6,649,1.8796,30700000,3.70
58.6,659,1.9469,31200000,3.83
60.6,670,2.0146,31700000,3.97
62.6,679,2.0827,32200000,4.10
64.7,687,2.1473,32600000,4.23
66.7,696,2.2152,33000000,4.36
68.7,704,2.2833,33400000,4.49
70.7,711,2.3482,33700000,4.62
72.7,718,2.4159,34000000,4.76
74.7,725,2.4842,34300000,4.89
76.7,730,2.5512,34600000,5.02
78.7,736,2.6162,34900000,5.15
80.7,742,2.6843,35100000,5.28
82.7,747,2.7517,35400000,5.42
84.8,752,2.8193,35600000,5.55
86.8,757,2.8873,35900000,5.68
88.8,762,2.9522,36100000,5.81
90.8,766,3.0198,36300000,5.94
92.8,771,3.0877,36500000,6.08
94.8,775,3.1553,36700000,6.21
96.9,779,3.2228,36900000,6.34
98.9,784,3.2883,37100000,6.47
101,788,3.3558,37300000,6.61
103,791,3.4232,37500000,6.74
105,795,3.4913,37700000,6.87
107,799,3.5563,37800000,7.00
109,802,3.6238,38000000,7.13
111,806,3.6917,38200000,7.27
113,809,3.7594,38300000,7.40
115,812,3.8269,38500000,7.53
117,816,3.8922,38600000,7.66
119,819,3.9599,38800000,7.80
121,822,4.0274,38900000,7.93
123,825,4.0953,39100000,8.06
125,829,4.1631,39300000,8.20
127,831,4.2278,39400000,8.32
129,834,4.2957,39500000,8.46
131,837,4.3636,39600000,8.59
133,840,4.4309,39800000,8.72
135,842,4.4986,39900000,8.86
137,845,4.5640,40000000,8.98
139,848,4.6314,40100000,9.12
141,850,4.6991,40300000,9.25
143,853,4.7671,40400000,9.38
145,855,4.8319,40500000,9.51
147,857,4.8996,40600000,9.64
149,860,4.9677,40700000,9.78
151,862,5.0350,40800000,9.91
153,864,5.1026,40900000,10.0
155,867,5.1682,41100000,10.2
157,869,5.2354,41100000,10.3
159,871,5.3030,41300000,10.4
161,873,5.3712,41400000,10.6
163,874,5.4385,41400000,10.7
165,877,5.5062,41500000,10.8
167,879,5.5716,41600000,11.0
169,881,5.6390,41700000,11.1
171,882,5.7067,41800000,11.2
173,884,5.7746,41900000,11.4
175,886,5.8422,42000000,11.5
177,888,5.9071,42100000,11.6
179,890,5.9748,42200000,11.8
181,891,6.0425,42200000,11.9
183,893,6.1100,42300000,12.0
185,895,6.1753,42400000,12.2
188,897,6.2429,42500000,12.3
190,898,6.3105,42500000,12.4
192,899,6.3784,42600000,12.6
194,901,6.4434,42700000,12.7
196,902,6.5109,42700000,12.8
198,904,6.5788,42800000,13.0
200,906,6.6466,42900000,13.1
202,906,6.7114,42900000,13.2
204,908,6.7793,43000000,13.3
206,909,6.8470,43100000,13.5
208,911,6.9144,43100000,13.6
210,912,6.9822,43200000,13.7
212,914,7.0503,43300000,13.9
214,915,7.1147,43300000,14.0
216,916,7.1824,43400000,14.1
218,917,7.2505,43400000,14.3
220,918,7.3177,43500000,14.4
222,919,7.3828,43600000,14.5
224,921,7.4509,43600000,14.7
226,923,7.5182,43700000,14.8
228,923,7.5858,43700000,14.9
230,924,7.6539,43800000,15.1
232,926,7.7213,43900000,15.2
234,927,7.7863,43900000,15.3
236,929,7.8544,44000000,15.5
238,929,7.9219,44000000,15.6
240,930,7.9894,44100000,15.7
242,932,8.0574,44100000,15.9
244,933,8.1223,44200000,16.0
246,933,8.1899,44200000,16.1
248,934,8.2579,44300000,16.3
250,935,8.3255,44300000,16.4
252,936,8.3930,44400000,16.5
254,938,8.4609,44400000,16.7
256,938,8.5259,44500000,16.8
258,939,8.5934,44500000,16.9
260,940,8.6613,44500000,17.0
262,941,8.7292,44600000,17.2
264,942,8.7966,44600000,17.3
266,942,8.8617,44600000,17.4
268,943,8.9297,44700000,17.6
270,944,8.9971,44700000,17.7
272,944,9.0647,44700000,17.8
274,946,9.1301,44800000,18.0
276,946,9.1975,44800000,18.1
278,947,9.2652,44800000,18.2
280,948,9.3333,44900000,18.4
282,949,9.4007,44900000,18.5
284,949,9.4658,44900000,18.6
286,950,9.5356,45000000,18.8
288,950,9.5996,45000000,18.9
290,951,9.6673,45100000,19.0
292,953,9.7354,45100000,19.2
294,953,9.8027,45200000,19.3
296,954,9.8703,45200000,19.4
298,955,9.9359,45200000,19.6
300,955,10.003,45300000,19.7
302,956,10.071,45300000,19.8
304,956,10.139,45300000,20.0
306,957,10.206,45300000,20.1
308,957,10.271,45300000,20.2
310,958,10.339,45400000,20.4
312,958,10.407,45400000,20.5
314,959,10.474,45400000,20.6
316,959,10.542,45400000,20.8
318,959,10.607,45400000,20.9
320,960,10.675,45500000,21.0
322,960,10.743,45500000,21.1
324,960,10.811,45500000,21.3
327,960,10.878,45500000,21.4
329,961,10.943,45500000,21.5
331,961,11.011,45500000,21.7
333,962,11.081,45500000,21.8
335,961,11.149,45500000,21.9
337,962,11.217,45500000,22.1
339,961,11.284,45500000,22.2
341,961,11.352,45500000,22.3
343,962,11.417,45600000,22.5
345,961,11.485,45500000,22.6
347,961,11.552,45500000,22.7
349,961,11.620,45500000,22.9
351,961,11.688,45500000,23.0
353,961,11.755,45500000,23.1
355,960,11.823,45500000,23.3
357,960,11.888,45500000,23.4
359,960,11.956,45500000,23.5
361,959,12.024,45400000,23.7
363,959,12.091,45400000,23.8
365,958,12.156,45400000,23.9
367,957,12.224,45400000,24.1
369,956,12.292,45300000,24.2
371,955,12.359,45200000,24.3
373,954,12.427,45200000,24.5
375,952,12.492,45100000,24.6
377,950,12.560,45000000,24.7
379,946,12.628,44800000,24.9
381,939,12.695,44500000,25.0
383,924,12.761,43800000,25.1