File: Manufacturing/Material_Testing_Data/Group 11/Group 11 Vertical (Questionable Data)/Test 103 Group_11_Vertical_03292019 114412 AM.csv
Time (sec),Force (N),Position (mm),Stress (Pa),Strain (%)
2.14,52.7,0.067800,2430000,0.133
4.15,80.8,0.13570,3730000,0.267
6.16,96.9,0.20350,4470000,0.401
8.16,126,0.26930,5800000,0.530
10.2,158,0.33700,7270000,0.663
12.2,191,0.40400,8830000,0.795
14.2,224,0.46910,10400000,0.923
16.2,257,0.53620,11900000,1.06
18.2,290,0.60400,13400000,1.19
20.2,323,0.67200,14900000,1.32
22.2,353,0.73930,16300000,1.46