File: Manufacturing/Material_Testing_Data/Group 11/Group 11 Vertical (Questionable Data)/Test 105 Group_11_Vertical_03292019 115023 AM.csv
Time (sec),Force (N),Position (mm),Stress (Pa),Strain (%)
2.23,60.6,0.067700,2740000,0.133
4.24,99.4,0.13500,4490000,0.266
6.25,123,0.20280,5570000,0.399
8.27,163,0.26820,7380000,0.528
10.3,209,0.33550,9440000,0.660
12.3,255,0.40320,11500000,0.794
14.3,299,0.47120,13500000,0.928
16.3,340,0.53790,15400000,1.06
18.3,377,0.60310,17000000,1.19
20.3,413,0.67110,18700000,1.32
22.4,444,0.73850,20100000,1.45
24.4,471,0.80610,21300000,1.59
26.4,495,0.87410,22400000,1.72
28.4,514,0.93890,23300000,1.85