File: Manufacturing/Material_Testing_Data/Group 10/Group 10 Vertical/Test 92 Group_10_Vertical_03292019 103414 AM.csv
Time (sec),Force (N),Position (mm),Stress (Pa),Strain (%)
2.21,48.9,0.067600,2280000,0.133
4.22,62.2,0.13530,2900000,0.266
6.23,62.6,0.20260,2920000,0.399
8.25,63.6,0.27050,2960000,0.532
10.3,69.0,0.33550,3220000,0.660
12.3,110,0.40290,5130000,0.793
14.3,152,0.47040,7070000,0.926
16.3,192,0.53790,8930000,1.06
18.3,229,0.60550,10700000,1.19
20.3,267,0.67040,12500000,1.32
22.3,304,0.73840,14200000,1.45
24.3,338,0.80580,15800000,1.59
26.4,369,0.87340,17200000,1.72