File: Manufacturing/Material_Testing_Data/Group 10/Group 10 Vertical/Test 91 Group_10_Vertical_03292019 103147 AM.csv
Time (sec),Force (N),Position (mm),Stress (Pa),Strain (%)
2.02,47.5,0.066000,2200000,0.130
4.04,62.1,0.13110,2870000,0.258
6.05,62.7,0.19860,2900000,0.391
8.07,64.6,0.26660,2990000,0.525
10.1,66.9,0.33420,3100000,0.658
12.1,99.0,0.40180,4580000,0.791
14.1,141,0.46710,6510000,0.919
16.1,182,0.53460,8430000,1.05
18.1,223,0.60220,10300000,1.19
20.2,262,0.67000,12100000,1.32
22.2,301,0.73790,13900000,1.45
24.2,336,0.80270,15600000,1.58
26.2,371,0.87060,17200000,1.71
28.2,405,0.93840,18700000,1.85