File: Manufacturing/Material_Testing_Data/Group 12/Group 12 Vertical/Test 114 Group_12_Vertical_03292019 125330 PM.csv
Time (sec),Force (N),Position (mm),Stress (Pa),Strain (%)
2.20,47.6,0.069000,2250000,0.136
4.22,76.4,0.13450,3620000,0.265
6.22,81.0,0.20240,3830000,0.398
8.24,111,0.26840,5280000,0.528
10.3,144,0.33580,6830000,0.661
12.3,179,0.40360,8480000,0.794
14.3,213,0.47080,10100000,0.927
16.3,246,0.53820,11600000,1.06
18.3,275,0.60320,13000000,1.19
20.3,303,0.67110,14300000,1.32
22.3,325,0.73890,15400000,1.45