File: Manufacturing/Material_Testing_Data/Group 12/Group 12 Vertical/Test 115 Group_12_Vertical_03292019 125627 PM.csv
Time (sec),Force (N),Position (mm),Stress (Pa),Strain (%)
2.22,46.4,0.068100,2260000,0.134
4.23,80.2,0.13510,3900000,0.266
6.27,101,0.20210,4930000,0.398
8.29,124,0.26970,6030000,0.531
10.3,157,0.33740,7640000,0.664
12.3,191,0.40480,9290000,0.797
14.3,225,0.47270,10900000,0.931
16.3,256,0.54050,12400000,1.06
18.4,283,0.60770,13800000,1.20
20.4,308,0.67250,15000000,1.32