File: Manufacturing/Material_Testing_Data/Group 1/Group 1 Vertical/Test 2 Group_1_Vertical_03202019 34441 PM.csv
Time (sec),Force (N),Position (mm),Stress (Pa),Strain (%)
2.12,35.0,0.065800,1660000,0.130
4.12,62.0,0.13120,2940000,0.258
6.13,65.8,0.19870,3120000,0.391
8.15,70.7,0.26630,3360000,0.524
10.2,91.0,0.33420,4320000,0.658
12.2,113,0.39920,5370000,0.786
14.2,138,0.46680,6570000,0.919
16.2,163,0.53460,7720000,1.05
18.2,187,0.60230,8880000,1.19
20.2,210,0.66980,9970000,1.32
22.3,231,0.73520,11000000,1.45
24.3,252,0.80290,12000000,1.58