File: Manufacturing/Material_Testing_Data/Group 1/Group 1 Vertical/Test 4 (test 5 broke before testing) Group_1_Vertical_03202019 35621 PM.csv
Time (sec),Force (N),Position (mm),Stress (Pa),Strain (%)
2.20,21.3,0.067400,1030000,0.133
4.22,39.6,0.13540,1920000,0.267
6.23,55.9,0.20360,2710000,0.401
8.24,67.9,0.26880,3290000,0.529
10.2,71.5,0.33690,3460000,0.663
12.3,73.7,0.40280,3570000,0.793
14.3,82.3,0.47040,3990000,0.926
16.3,93.3,0.53630,4520000,1.06
18.3,103,0.60450,5000000,1.19
20.3,114,0.67200,5540000,1.32
22.3,124,0.73770,6000000,1.45